<?xml version='1.0' encoding='utf-8'?>
<mujoco model="dahuafuhe_stage1_playback"><compiler angle="radian" autolimits="true" balanceinertia="true" /><option timestep="0.002" gravity="0 0 -9.81" /><visual><global offwidth="1280" offheight="960" /></visual><asset><mesh name="dahuafuhe_v2_mesh" file="/home/jetson/tashan/curobo2_demo_ws/robot_assets/dahuafuhe/robot/curobo/meshes/dahuafuhe_v2.stl" scale="1 1 1" /><mesh name="XMC7-R850-W4X3B4_base_mesh" file="/home/jetson/tashan/curobo2_demo_ws/robot_assets/dahuafuhe/robot/curobo/meshes/rokae_cr7_meshes/XMC7-R850-W4X3B4_base.stl" scale="0.001 0.001 0.001" /><mesh name="XMC7-R850-W4X3B4_link1_mesh" file="/home/jetson/tashan/curobo2_demo_ws/robot_assets/dahuafuhe/robot/curobo/meshes/rokae_cr7_meshes/XMC7-R850-W4X3B4_link1.stl" scale="0.001 0.001 0.001" /><mesh name="XMC7-R850-W4X3B4_link2_mesh" file="/home/jetson/tashan/curobo2_demo_ws/robot_assets/dahuafuhe/robot/curobo/meshes/rokae_cr7_meshes/XMC7-R850-W4X3B4_link2.stl" scale="0.001 0.001 0.001" /><mesh name="XMC7-R850-W4X3B4_link3_mesh" file="/home/jetson/tashan/curobo2_demo_ws/robot_assets/dahuafuhe/robot/curobo/meshes/rokae_cr7_meshes/XMC7-R850-W4X3B4_link3.stl" scale="0.001 0.001 0.001" /><mesh name="XMC7-R850-W4X3B4_link4_mesh" file="/home/jetson/tashan/curobo2_demo_ws/robot_assets/dahuafuhe/robot/curobo/meshes/rokae_cr7_meshes/XMC7-R850-W4X3B4_link4.stl" scale="0.001 0.001 0.001" /><mesh name="XMC7-R850-W4X3B4_link5_mesh" file="/home/jetson/tashan/curobo2_demo_ws/robot_assets/dahuafuhe/robot/curobo/meshes/rokae_cr7_meshes/XMC7-R850-W4X3B4_link5.stl" scale="0.001 0.001 0.001" /><mesh name="XMC7-R850-W4X3B4_link6_mesh" file="/home/jetson/tashan/curobo2_demo_ws/robot_assets/dahuafuhe/robot/curobo/meshes/rokae_cr7_meshes/XMC7-R850-W4X3B4_link6.stl" scale="0.001 0.001 0.001" /></asset><worldbody><light pos="1.5 -0.5 2.5" dir="-1 0 -1" /><geom name="ground" type="plane" size="2 2 0.1" rgba="0.94 0.94 0.96 1" /><body name="Link_00" pos="0 0 0" euler="0 0 0"><inertial pos="0 0 0" mass="0.1" diaginertia="0.001 0.001 0.001" /><geom name="Link_00_XMC7-R850-W4X3B4_base_geom" type="mesh" mesh="XMC7-R850-W4X3B4_base_mesh" rgba="0.77 0.79 0.84 1" contype="0" conaffinity="0" group="1" /><body name="Link_01" pos="0 0 0" euler="0 0 0"><inertial pos="0 0 0" mass="5.489" diaginertia="0.04930387 0.03722179 0.02823666" /><joint name="joint_1" type="hinge" axis="0 0 1" damping="1" range="-6.2832 6.2832" /><geom name="Link_01_XMC7-R850-W4X3B4_link1_geom" type="mesh" mesh="XMC7-R850-W4X3B4_link1_mesh" rgba="0.77 0.79 0.84 1" contype="0" conaffinity="0" group="1" /><body name="Link_02" pos="0 0 0.296" euler="0 0 0"><inertial pos="0 0 0" mass="7.281" diaginertia="0.34218339 0.33734902 0.02516474" /><joint name="joint_2" type="hinge" axis="0 1 0" damping="1" range="-6.2832 6.2832" /><geom name="Link_02_XMC7-R850-W4X3B4_link2_geom" type="mesh" mesh="XMC7-R850-W4X3B4_link2_mesh" rgba="0.77 0.79 0.84 1" contype="0" conaffinity="0" group="1" /><body name="Link_03" pos="0 0 0.49" euler="0 0 0"><inertial pos="0 0 0" mass="2.872" diaginertia="0.02089959 0.01307617 0.01213645" /><joint name="joint_3" type="hinge" axis="0 -1 0" damping="1" range="-6.2832 6.2832" /><geom name="Link_03_XMC7-R850-W4X3B4_link3_geom" type="mesh" mesh="XMC7-R850-W4X3B4_link3_mesh" rgba="0.77 0.79 0.84 1" contype="0" conaffinity="0" group="1" /><body name="Link_04" pos="0 0 0.36" euler="0 0 0"><inertial pos="0 0 0" mass="2.823" diaginertia="0.03166823 0.03030476 0.00568926" /><joint name="joint_4" type="hinge" axis="0 0 1" damping="1" range="-6.2832 6.2832" /><geom name="Link_04_XMC7-R850-W4X3B4_link4_geom" type="mesh" mesh="XMC7-R850-W4X3B4_link4_mesh" rgba="0.77 0.79 0.84 1" contype="0" conaffinity="0" group="1" /><body name="Link_05" pos="0 -0.15 0.004" euler="0 0 0"><inertial pos="0 0 0" mass="2.34" diaginertia="0.00953363 0.00581555 0.00692085" /><joint name="joint_5" type="hinge" axis="0 -1 0" damping="1" range="-6.2832 6.2832" /><geom name="Link_05_XMC7-R850-W4X3B4_link5_geom" type="mesh" mesh="XMC7-R850-W4X3B4_link5_mesh" rgba="0.77 0.79 0.84 1" contype="0" conaffinity="0" group="1" /><body name="Link_06" pos="0 0 0.123" euler="0 0 0"><inertial pos="0 0 0" mass="1.142" diaginertia="0.00217743 0.0021883 0.00125122" /><joint name="joint_6" type="hinge" axis="0 0 1" damping="1" range="-6.2832 6.2832" /><geom name="Link_06_XMC7-R850-W4X3B4_link6_geom" type="mesh" mesh="XMC7-R850-W4X3B4_link6_mesh" rgba="0.77 0.79 0.84 1" contype="0" conaffinity="0" group="1" /><body name="hand_link" pos="-0.01 -0.043 0.075" euler="0 0 -1.571"><inertial pos="0 0 0" mass="0.1" diaginertia="0.001 0.001 0.001" /><geom name="hand_link_dahuafuhe_v2_geom" type="mesh" mesh="dahuafuhe_v2_mesh" rgba="0.77 0.79 0.84 1" contype="0" conaffinity="0" group="1" /></body><body name="tool0" pos="0 0.0481 0.2473" euler="0.698131689 0 0"><inertial pos="0 0 0" mass="0.1" diaginertia="0.001 0.001 0.001" /><site name="tool0_site" pos="0 0 0" size="0.012" rgba="1 0.2 0.2 1" /></body></body></body></body></body></body></body></body></worldbody></mujoco>