<?xml version='1.0' encoding='utf-8'?>
<mujoco model="rokae_stage1_playback"><compiler angle="radian" autolimits="true" balanceinertia="true" /><option timestep="0.002" gravity="0 0 -9.81" /><visual><global offwidth="1280" offheight="960" /></visual><asset><mesh name="XMS5-R800-W4G3B4C_base_mesh" file="/home/tanshan/rep/curoboV2_demo/robot_assets/ROKAE/robot/curobo/meshes/xms5_r800_w4g3b4c_meshes/XMS5-R800-W4G3B4C_base.stl" scale="0.001 0.001 0.001" /><mesh name="XMS5-R800-W4G3B4C_link1_mesh" file="/home/tanshan/rep/curoboV2_demo/robot_assets/ROKAE/robot/curobo/meshes/xms5_r800_w4g3b4c_meshes/XMS5-R800-W4G3B4C_link1.stl" scale="0.001 0.001 0.001" /><mesh name="XMS5-R800-W4G3B4C_link2_mesh" file="/home/tanshan/rep/curoboV2_demo/robot_assets/ROKAE/robot/curobo/meshes/xms5_r800_w4g3b4c_meshes/XMS5-R800-W4G3B4C_link2.stl" scale="0.001 0.001 0.001" /><mesh name="XMS5-R800-W4G3B4C_link3_mesh" file="/home/tanshan/rep/curoboV2_demo/robot_assets/ROKAE/robot/curobo/meshes/xms5_r800_w4g3b4c_meshes/XMS5-R800-W4G3B4C_link3.stl" scale="0.001 0.001 0.001" /><mesh name="XMS5-R800-W4G3B4C_link4_mesh" file="/home/tanshan/rep/curoboV2_demo/robot_assets/ROKAE/robot/curobo/meshes/xms5_r800_w4g3b4c_meshes/XMS5-R800-W4G3B4C_link4.stl" scale="0.001 0.001 0.001" /><mesh name="XMS5-R800-W4G3B4C_link5_mesh" file="/home/tanshan/rep/curoboV2_demo/robot_assets/ROKAE/robot/curobo/meshes/xms5_r800_w4g3b4c_meshes/XMS5-R800-W4G3B4C_link5.stl" scale="0.001 0.001 0.001" /><mesh name="XMS5-R800-W4G3B4C_link6_mesh" file="/home/tanshan/rep/curoboV2_demo/robot_assets/ROKAE/robot/curobo/meshes/xms5_r800_w4g3b4c_meshes/XMS5-R800-W4G3B4C_link6.stl" scale="0.001 0.001 0.001" /></asset><worldbody><light pos="1.5 -0.5 2.5" dir="-1 0 -1" /><geom name="ground" type="plane" size="2 2 0.1" rgba="0.94 0.94 0.96 1" /><body name="XMS5-R800-W4G3B4C_base" pos="0 0 0" euler="0 0 0"><inertial pos="0 0 0" mass="0.1" diaginertia="0.001 0.001 0.001" /><geom name="XMS5-R800-W4G3B4C_base_XMS5-R800-W4G3B4C_base_geom" type="mesh" mesh="XMS5-R800-W4G3B4C_base_mesh" rgba="0.77 0.79 0.84 1" contype="0" conaffinity="0" group="1" /><body name="XMS5-R800-W4G3B4C_link1" pos="0 0 0.328" euler="0 0 0"><inertial pos="0 0 0" mass="3.167" diaginertia="0.03116799 0.03071271 0.0058774" /><joint name="XMS5-R800-W4G3B4C_joint_1" type="hinge" axis="0 0 1" damping="1" range="-6.2832 6.2832" /><geom name="XMS5-R800-W4G3B4C_link1_XMS5-R800-W4G3B4C_link1_geom" type="mesh" mesh="XMS5-R800-W4G3B4C_link1_mesh" rgba="0.77 0.79 0.84 1" contype="0" conaffinity="0" group="1" /><body name="XMS5-R800-W4G3B4C_link2" pos="0 0 0" euler="0 0 0"><inertial pos="0 0 0" mass="4.291" diaginertia="0.14042515 0.14040198 0.01264775" /><joint name="XMS5-R800-W4G3B4C_joint_2" type="hinge" axis="0 1 0" damping="1" range="-2.7925 2.618" /><geom name="XMS5-R800-W4G3B4C_link2_XMS5-R800-W4G3B4C_link2_geom" type="mesh" mesh="XMS5-R800-W4G3B4C_link2_mesh" rgba="0.77 0.79 0.84 1" contype="0" conaffinity="0" group="1" /><body name="XMS5-R800-W4G3B4C_link3" pos="0.05 0 0.4" euler="0 0 0"><inertial pos="0 0 0" mass="2.018" diaginertia="0.02103842 0.02167667 0.00429357" /><joint name="XMS5-R800-W4G3B4C_joint_3" type="hinge" axis="0 -1 0" damping="1" range="-2.9671 2.4435" /><geom name="XMS5-R800-W4G3B4C_link3_XMS5-R800-W4G3B4C_link3_geom" type="mesh" mesh="XMS5-R800-W4G3B4C_link3_mesh" rgba="0.77 0.79 0.84 1" contype="0" conaffinity="0" group="1" /><body name="XMS5-R800-W4G3B4C_link4" pos="-0.05 0 0.4" euler="0 0 0"><inertial pos="0 0 0" mass="2.005" diaginertia="0.01325119 0.01255684 0.00274485" /><joint name="XMS5-R800-W4G3B4C_joint_4" type="hinge" axis="0 0 1" damping="1" range="-6.2832 6.2832" /><geom name="XMS5-R800-W4G3B4C_link4_XMS5-R800-W4G3B4C_link4_geom" type="mesh" mesh="XMS5-R800-W4G3B4C_link4_mesh" rgba="0.77 0.79 0.84 1" contype="0" conaffinity="0" group="1" /><body name="XMS5-R800-W4G3B4C_link5" pos="0 0.136 0" euler="0 0 0"><inertial pos="0 0 0" mass="1.507" diaginertia="0.00503262 0.00261442 0.0039448" /><joint name="XMS5-R800-W4G3B4C_joint_5" type="hinge" axis="0 -1 0" damping="1" range="-6.2832 6.2832" /><geom name="XMS5-R800-W4G3B4C_link5_XMS5-R800-W4G3B4C_link5_geom" type="mesh" mesh="XMS5-R800-W4G3B4C_link5_mesh" rgba="0.77 0.79 0.84 1" contype="0" conaffinity="0" group="1" /><body name="XMS5-R800-W4G3B4C_link6" pos="0 0 0.1035" euler="0 0 0"><inertial pos="0 0 0" mass="0.634" diaginertia="0.00099702 0.00100253 0.00044795" /><joint name="XMS5-R800-W4G3B4C_joint_6" type="hinge" axis="0 0 1" damping="1" range="-6.2832 6.2832" /><geom name="XMS5-R800-W4G3B4C_link6_XMS5-R800-W4G3B4C_link6_geom" type="mesh" mesh="XMS5-R800-W4G3B4C_link6_mesh" rgba="0.77 0.79 0.84 1" contype="0" conaffinity="0" group="1" /><body name="tool0" pos="0 0 0" euler="0 0 0"><inertial pos="0 0 0" mass="0.1" diaginertia="0.001 0.001 0.001" /><site name="tool0_site" pos="0 0 0" size="0.012" rgba="1 0.2 0.2 1" /></body></body></body></body></body></body></body></body></worldbody></mujoco>