<?xml version='1.0' encoding='utf-8'?>
<mujoco model="franka_stage1_playback"><compiler angle="radian" autolimits="true" balanceinertia="true" /><option timestep="0.002" gravity="0 0 -9.81" /><visual><global offwidth="1280" offheight="960" /></visual><asset><mesh name="finger_mesh" file="/home/jetson/tashan/curobo2_demo_ws/third_party/curobo/curobo/content/assets/robot/franka_description/meshes/collision/finger.obj" scale="1 1 1" /><mesh name="hand_mesh" file="/home/jetson/tashan/curobo2_demo_ws/third_party/curobo/curobo/content/assets/robot/franka_description/meshes/collision/hand.obj" scale="1 1 1" /><mesh name="link0_mesh" file="/home/jetson/tashan/curobo2_demo_ws/third_party/curobo/curobo/content/assets/robot/franka_description/meshes/collision/link0.obj" scale="1 1 1" /><mesh name="link1_mesh" file="/home/jetson/tashan/curobo2_demo_ws/third_party/curobo/curobo/content/assets/robot/franka_description/meshes/collision/link1.obj" scale="1 1 1" /><mesh name="link2_mesh" file="/home/jetson/tashan/curobo2_demo_ws/third_party/curobo/curobo/content/assets/robot/franka_description/meshes/collision/link2.obj" scale="1 1 1" /><mesh name="link3_mesh" file="/home/jetson/tashan/curobo2_demo_ws/third_party/curobo/curobo/content/assets/robot/franka_description/meshes/collision/link3.obj" scale="1 1 1" /><mesh name="link4_mesh" file="/home/jetson/tashan/curobo2_demo_ws/third_party/curobo/curobo/content/assets/robot/franka_description/meshes/collision/link4.obj" scale="1 1 1" /><mesh name="link5_mesh" file="/home/jetson/tashan/curobo2_demo_ws/third_party/curobo/curobo/content/assets/robot/franka_description/meshes/collision/link5.obj" scale="1 1 1" /><mesh name="link6_mesh" file="/home/jetson/tashan/curobo2_demo_ws/third_party/curobo/curobo/content/assets/robot/franka_description/meshes/collision/link6.obj" scale="1 1 1" /><mesh name="link7_mesh" file="/home/jetson/tashan/curobo2_demo_ws/third_party/curobo/curobo/content/assets/robot/franka_description/meshes/collision/link7.obj" scale="1 1 1" /></asset><worldbody><light pos="1.5 0 2.5" dir="-1 0 -1" /><geom name="ground" type="plane" size="2 2 0.1" rgba="0.94 0.94 0.96 1" /><body name="base_link" pos="0 0 0"><inertial pos="0 0 0" mass="0.1" diaginertia="0.001 0.001 0.001" /><body name="panda_link0" pos="0 0 0" euler="0 0 0"><inertial pos="0 0 0" mass="2.3966" diaginertia="1e-06 0.0115 0.0085" /><geom name="panda_link0_link0_geom" type="mesh" mesh="link0_mesh" rgba="0.77 0.79 0.84 1" contype="0" conaffinity="0" group="1" /><body name="panda_link1" pos="0 0 0.333" euler="0 0 0"><inertial pos="0 0 0" mass="2.797" diaginertia="0.0156 0.01439 0.005" /><joint name="panda_joint1" type="hinge" axis="0 0 1" damping="10" range="-2.8973 2.8973" /><geom name="panda_link1_link1_geom" type="mesh" mesh="link1_mesh" rgba="0.77 0.79 0.84 1" contype="0" conaffinity="0" group="1" /><body name="panda_link2" pos="0 0 0" euler="-1.57079633 0 0"><inertial pos="0 0 0" mass="2.542" diaginertia="0.0166 0.0046 0.015" /><joint name="panda_joint2" type="hinge" axis="0 0 1" damping="10" range="-1.7628 1.7628" /><geom name="panda_link2_link2_geom" type="mesh" mesh="link2_mesh" rgba="0.77 0.79 0.84 1" contype="0" conaffinity="0" group="1" /><body name="panda_link3" pos="0 -0.316 0" euler="1.57079633 0 0"><inertial pos="0 0 0" mass="2.2513" diaginertia="0.006 0.0086 0.0065" /><joint name="panda_joint3" type="hinge" axis="0 0 1" damping="10" range="-2.8973 2.8973" /><geom name="panda_link3_link3_geom" type="mesh" mesh="link3_mesh" rgba="0.77 0.79 0.84 1" contype="0" conaffinity="0" group="1" /><body name="panda_link4" pos="0.0825 0 0" euler="1.57079633 0 0"><inertial pos="0 0 0" mass="2.2037" diaginertia="0.0156 0.01439 0.005" /><joint name="panda_joint4" type="hinge" axis="0 0 1" damping="10" range="-3.0718 -0.0698" /><geom name="panda_link4_link4_geom" type="mesh" mesh="link4_mesh" rgba="0.77 0.79 0.84 1" contype="0" conaffinity="0" group="1" /><body name="panda_link5" pos="-0.0825 0.384 0" euler="-1.57079633 0 0"><inertial pos="0 0 0" mass="2.2855" diaginertia="0.0229701478 0.0209506092 0.00430606551" /><joint name="panda_joint5" type="hinge" axis="0 0 1" damping="10" range="-2.8973 2.8973" /><geom name="panda_link5_link5_geom" type="mesh" mesh="link5_mesh" rgba="0.77 0.79 0.84 1" contype="0" conaffinity="0" group="1" /><body name="panda_link6" pos="0 0 0" euler="1.57079633 0 0"><inertial pos="0 0 0" mass="1.353" diaginertia="0.00087964522 0.00277796968 0.00286701969" /><joint name="panda_joint6" type="hinge" axis="0 0 1" damping="10" range="-0.0175 3.7525" /><geom name="panda_link6_link6_geom" type="mesh" mesh="link6_mesh" rgba="0.77 0.79 0.84 1" contype="0" conaffinity="0" group="1" /><body name="panda_link7" pos="0.088 0 0" euler="1.57079633 0 0"><inertial pos="0 0 0" mass="0.35973" diaginertia="0.00019541063 0.00019210361 0.00017936256" /><joint name="panda_joint7" type="hinge" axis="0 0 1" damping="10" range="-2.8973 2.8973" /><geom name="panda_link7_link7_geom" type="mesh" mesh="link7_mesh" rgba="0.77 0.79 0.84 1" contype="0" conaffinity="0" group="1" /><body name="panda_link8" pos="0 0 0.107" euler="0 0 0"><inertial pos="0 0 0" mass="0.1" diaginertia="0.001 0.001 0.001" /><body name="panda_hand" pos="0 0 0" euler="0 0 -0.785398163"><inertial pos="0 0 0" mass="1" diaginertia="0.00019541063 0.00019210361 0.00017936256" /><geom name="panda_hand_hand_geom" type="mesh" mesh="hand_mesh" rgba="0.77 0.79 0.84 1" contype="0" conaffinity="0" group="1" /><site name="panda_hand_site" pos="0 0 0" size="0.012" rgba="1 0.2 0.2 1" /><body name="panda_leftfinger" pos="0 0 0.0584" euler="0 0 0"><inertial pos="0 0 0" mass="0.1" diaginertia="0.001 0.001 0.001" /><joint name="panda_finger_joint1" type="slide" axis="0 1 0" damping="10" range="0 0.04" /><geom name="panda_leftfinger_finger_geom" type="mesh" mesh="finger_mesh" rgba="0.77 0.79 0.84 1" contype="0" conaffinity="0" group="1" /></body><body name="panda_rightfinger" pos="0 0 0.0584" euler="0 0 0"><inertial pos="0 0 0" mass="0.1" diaginertia="0.001 0.001 0.001" /><joint name="panda_finger_joint2" type="slide" axis="0 -1 0" damping="10" range="0 0.04" /><geom name="panda_rightfinger_finger_geom" type="mesh" mesh="finger_mesh" rgba="0.77 0.79 0.84 1" contype="0" conaffinity="0" group="1" /></body><body name="ee_link" pos="0 0 0.1" euler="0 0 0"><inertial pos="0 0 0" mass="0.1" diaginertia="0.001 0.001 0.001" /></body></body></body><body name="right_gripper" pos="0 0 0.207" euler="0 0 2.35619449"><inertial pos="0 0 0" mass="0.01" diaginertia="0.0001 0.0001 0.0001" /></body></body></body></body></body></body></body></body></body></body></worldbody></mujoco>